Candidate: CVE-2020-29651
PublicDate: 2020-12-09 07:15:00 UTC
References:
 https://cve.mitre.org/cgi-bin/cvename.cgi?name=CVE-2020-29651
 https://github.com/pytest-dev/py/issues/256
 https://github.com/pytest-dev/py/pull/257
 https://github.com/pytest-dev/py/pull/257/commits/4a9017dc6199d2a564b6e4b0aa39d6d8870e4144
Description:
 A denial of service via regular expression in the py.path.svnwc component
 of py (aka python-py) through 1.9.0 could be used by attackers to cause a
 compute-time denial of service attack by supplying malicious input to the
 blame functionality.
Ubuntu-Description:
Notes:
Mitigation:
Bugs:
Priority: medium
Discovered-by:
Assigned-to:
CVSS:


Patches_python-py:
upstream_python-py: needs-triage
precise/esm_python-py: DNE
trusty_python-py: ignored (out of standard support)
trusty/esm_python-py: DNE
xenial_python-py: needs-triage
bionic_python-py: needs-triage
focal_python-py: needs-triage
groovy_python-py: needs-triage
devel_python-py: needs-triage
